<?xml version="1.0" encoding="utf-8"?>
<!-- This URDF was automatically created by SolidWorks to URDF Exporter! Originally created by Stephen Brawner (brawner@gmail.com) 
     Commit Version: 1.6.0-4-g7f85cfe  Build Version: 1.6.7995.38578
     For more information, please see http://wiki.ros.org/sw_urdf_exporter -->
<robot
  name="urdf2">
  <link name="world_link"/>
  <joint 
    name="base_joint" type="fixed">
    <parent link="world_link"/>
    <child link="base_link"/>
    <origin xyz="0 0 0" rpy="0 0 0"/>
    <axis xyz="0 0 0"/>
  </joint>
  <link
    name="base_link">
    <inertial>
      <origin
        xyz="-6.1438E-09 -0.011169 0.020052"
        rpy="0 0 0" />
      <mass
        value="0.50571" />
      <inertia
        ixx="0.00096003"
        ixy="1.9768E-09"
        ixz="6.136E-10"
        iyy="0.00090083"
        iyz="6.5015E-06"
        izz="0.001388" />
    </inertial>
    <visual>
      <origin
        xyz="0 0 0"
        rpy="0 0 0" />
      <geometry>
        <mesh
          filename="package://urdf2/meshes/base_link.STL" />
      </geometry>
      <material
        name="">
        <color
          rgba="0.75294 0.75294 0.75294 1" />
      </material>
    </visual>
    <collision>
      <origin
        xyz="0 0 0"
        rpy="0 0 0" />
      <geometry>
        <mesh
          filename="package://urdf2/meshes/base_link.STL" />
      </geometry>
    </collision>
  </link>
  <link
    name="l1">
    <inertial>
      <origin
        xyz="1.2953E-07 1.2859E-07 -0.015785"
        rpy="0 0 0" />
      <mass
        value="0.47776" />
      <inertia
        ixx="0.00068931"
        ixy="-2.6856E-11"
        ixz="-8.3133E-10"
        iyy="0.00068088"
        iyz="-8.2529E-10"
        izz="0.00094264" />
    </inertial>
    <visual>
      <origin
        xyz="0 0 0"
        rpy="0 0 0" />
      <geometry>
        <mesh
          filename="package://urdf2/meshes/l1.STL" />
      </geometry>
      <material
        name="">
        <color
          rgba="0.75294 0.75294 0.75294 1" />
      </material>
    </visual>
    <collision>
      <origin
        xyz="0 0 0"
        rpy="0 0 0" />
      <geometry>
        <mesh
          filename="package://urdf2/meshes/l1.STL" />
      </geometry>
    </collision>
  </link>
  <joint
    name="j1"
    type="continuous">
    <origin
      xyz="0 0 0.05725"
      rpy="0 0 0" />
    <parent
      link="base_link" />
    <child
      link="l1" />
    <axis
      xyz="0 0 1" />
    <limit
      lower="0"
      upper="6.284"
      effort="1"
      velocity="15.7" />
  </joint>
  <link
    name="l2">
    <inertial>
      <origin
        xyz="0.014582 -0.044276 2.6562E-06"
        rpy="0 0 0" />
      <mass
        value="0.36853" />
      <inertia
        ixx="0.0008527"
        ixy="-1.2859E-09"
        ixz="9.0146E-09"
        iyy="0.00087577"
        iyz="8.1623E-08"
        izz="0.00084714" />
    </inertial>
    <visual>
      <origin
        xyz="0 0 0"
        rpy="0 0 0" />
      <geometry>
        <mesh
          filename="package://urdf2/meshes/l2.STL" />
      </geometry>
      <material
        name="">
        <color
          rgba="0.75294 0.75294 0.75294 1" />
      </material>
    </visual>
    <collision>
      <origin
        xyz="0 0 0"
        rpy="0 0 0" />
      <geometry>
        <mesh
          filename="package://urdf2/meshes/l2.STL" />
      </geometry>
    </collision>
  </link>
  <joint
    name="j2"
    type="revolute">
    <origin
      xyz="0.0145 0 0.04"
      rpy="1.5708 0 3.1416" />
    <parent
      link="l1" />
    <child
      link="l2" />
    <axis
      xyz="1 0 0" />
    <limit
      lower="-1.5710"
      upper="1.5710"
      effort="0.5"
      velocity="31.4" />
  </joint>
  <link
    name="l3">
    <inertial>
      <origin
        xyz="0.036174 -0.19646 0.01907"
        rpy="0 0 0" />
      <mass
        value="0.36255" />
      <inertia
        ixx="0.00085252"
        ixy="2.9772E-09"
        ixz="-6.3162E-10"
        iyy="0.0010923"
        iyz="-2.6361E-07"
        izz="0.00062587" />
    </inertial>
    <visual>
      <origin
        xyz="0 0 0"
        rpy="0 0 0" />
      <geometry>
        <mesh
          filename="package://urdf2/meshes/l3.STL" />
      </geometry>
      <material
        name="">
        <color
          rgba="0.75294 0.75294 0.75294 1" />
      </material>
    </visual>
    <collision>
      <origin
        xyz="0 0 0"
        rpy="0 0 0" />
      <geometry>
        <mesh
          filename="package://urdf2/meshes/l3.STL" />
      </geometry>
    </collision>
  </link>
  <joint
    name="j3"
    type="revolute">
    <origin
      xyz="-0.0195 0.17 0"
      rpy="0 0 0" />
    <parent
      link="l2" />
    <child
      link="l3" />
    <axis
      xyz="-1 0 0" />
    <limit
      lower="0"
      upper="3.142"
      effort="1"
      velocity="15.7" />
  </joint>
  <link
    name="l4">
    <inertial>
      <origin
        xyz="-0.0049511 -0.23516 -0.15806"
        rpy="0 0 0" />
      <mass
        value="0.30407" />
      <inertia
        ixx="0.00061814"
        ixy="2.6323E-09"
        ixz="-3.9108E-09"
        iyy="0.00086659"
        iyz="-1.3982E-07"
        izz="0.00061915" />
    </inertial>
    <visual>
      <origin
        xyz="0 0 0"
        rpy="0 0 0" />
      <geometry>
        <mesh
          filename="package://urdf2/meshes/l4.STL" />
      </geometry>
      <material
        name="">
        <color
          rgba="0.75294 0.75294 0.75294 1" />
      </material>
    </visual>
    <collision>
      <origin
        xyz="0 0 0"
        rpy="0 0 0" />
      <geometry>
        <mesh
          filename="package://urdf2/meshes/l4.STL" />
      </geometry>
    </collision>
  </link>
  <joint
    name="j4"
    type="revolute">
    <origin
      xyz="0.038909 0 0.18"
      rpy="0 0 0" />
    <parent
      link="l3" />
    <child
      link="l4" />
    <axis
      xyz="1 0 0" />
    <limit
      lower="-1.5710"
      upper="1.5710"
      effort="1"
      velocity="15.7" />
  </joint>
  <transmission name="link_1_trans">
    <type>transmission_interface/SimpleTransmission</type>
    <joint name="j1">
      <hardwareInterface>hardware_interface/PositionJointInterface</hardwareInterface>
    </joint>
    <actuator name="link_1_motor">
      <hardwareInterface>hardware_interface/PositionJointInterface</hardwareInterface>
      <mechanicalReduction>1</mechanicalReduction>
    </actuator>
  </transmission>
  <transmission name="link_2_trans">
    <type>transmission_interface/SimpleTransmission</type>
    <joint name="j2">
      <hardwareInterface>hardware_interface/PositionJointInterface</hardwareInterface>
    </joint>
    <actuator name="link_2_motor">
      <hardwareInterface>hardware_interface/PositionJointInterface</hardwareInterface>
      <mechanicalReduction>1</mechanicalReduction>
    </actuator>
  </transmission>
  <transmission name="link_3_trans">
    <type>transmission_interface/SimpleTransmission</type>
    <joint name="j3">
      <hardwareInterface>hardware_interface/PositionJointInterface</hardwareInterface>
    </joint>
    <actuator name="link_3_motor">
      <hardwareInterface>hardware_interface/PositionJointInterface</hardwareInterface>
      <mechanicalReduction>1</mechanicalReduction>
    </actuator>
  </transmission>
  <transmission name="link_4_trans">
    <type>transmission_interface/SimpleTransmission</type>
    <joint name="j4">
      <hardwareInterface>hardware_interface/PositionJointInterface</hardwareInterface>
    </joint>
    <actuator name="link_4_motor">
      <hardwareInterface>hardware_interface/PositionJointInterface</hardwareInterface>
      <mechanicalReduction>1</mechanicalReduction>
    </actuator>
  </transmission>
  <gazebo>
    <plugin name="gazebo_ros_control" filename="libgazebo_ros_control.so">
      <robotNamespace>/</robotNamespace>
    </plugin>
  </gazebo>
  <gazebo reference="l1">
    <selfCollide>true</selfCollide>
  </gazebo>
  <gazebo reference="l2">
    <selfCollide>true</selfCollide>
  </gazebo>
  <gazebo reference="l3">
    <selfCollide>true</selfCollide>
  </gazebo>
  <gazebo reference="l4">
    <selfCollide>true</selfCollide>
  </gazebo>
</robot>